<?xml version="1.0"?>
<robot xmlns:xacro="http://www.ros.org/wiki/xacro">

    <xacro:include filename="inertial_macros.xacro"/>
<!-- Base Link -->
    <link name="base_link">  
        <visual>  
            <geometry>  
                <box size="0.5 0.2 0.1"/>  
            </geometry>  
            <material name="blue">  
                <color rgba="0 0 1 1"/>  
            </material>  
        </visual>  
    </link>  

  <!-- Front Left Wheel -->
    <link name="front_left_wheel">  
        <visual>  
            <geometry>  
                <cylinder radius="0.05" length="0.04"/>  
            </geometry>  
            <material name="black">  
                <color rgba="0 0 0 1"/>  
            </material>  
        </visual>  
    </link>  

  <!-- Front Right Wheel -->
    <link name="front_right_wheel">  
        <visual>  
            <geometry>  
                <cylinder radius="0.05" length="0.04"/>  
            </geometry>  
            <material name="black">  
                <color rgba="0 0 0 1"/>  
            </material>  
        </visual>  
    </link>  

  <!-- Rear Left Wheel -->
    <link name="rear_left_wheel">  
        <visual>  
            <geometry>  
                <cylinder radius="0.05" length="0.04"/>  
            </geometry>  
            <material name="black">  
                <color rgba="0 0 0 1"/>  
            </material>  
        </visual>  
    </link>  

  <!-- Rear Right Wheel -->
    <link name="rear_right_wheel">  
        <visual>  
            <geometry>  
                <cylinder radius="0.05" length="0.04"/>  
            </geometry>  
            <material name="black">  
                <color rgba="0 0 0 1"/>  
            </material>  
        </visual>  
    </link>  

<!-- Front Left Wheel Joint (Steering) with motor -->
<joint name="base_to_front_left_wheel" type="revolute">
    <parent link="base_link"/>
    <child link="front_left_wheel"/>
    <origin xyz="0.2 0.11 0" rpy="-${pi/2} 0 0"/>
    <axis xyz="0 0 1"/>
    <dynamics damping="0.1" friction="0.1"/>
    <limit lower="-1.57" upper="1.57" effort="50" velocity="1"/>
</joint>

<!-- Front Right Wheel Joint (Steering) with motor -->
<joint name="base_to_front_right_wheel" type="revolute">
    <parent link="base_link"/>
    <child link="front_right_wheel"/>
    <origin xyz="0.2 -0.11 0" rpy="${pi/2} 0 0"/>
    <axis xyz="0 0 1"/>
    <dynamics damping="0.1" friction="0.1"/>
    <limit lower="-1.57" upper="1.57" effort="50" velocity="1"/>
</joint>

  <!-- Rear Left Wheel Joint (Fixed) -->
    <joint name="base_to_rear_left_wheel" type="continuous">  
        <parent link="base_link"/>  
        <child link="rear_left_wheel"/>  
        <origin xyz="-0.2 0.11 0" rpy="-${pi/2}  0 0"/>
        <axis xyz="0 0 1"/>
    </joint>  

  <!-- Rear Right Wheel Joint (Fixed) -->
    <joint name="base_to_rear_right_wheel" type="continuous">  
        <parent link="base_link"/>  
        <child link="rear_right_wheel"/>  
        <origin xyz="-0.2 -0.11 0" rpy="-${pi/2}  0 0"/>  
        <axis xyz="0 0 1"/>
    </joint>  


</robot>
